Traceback (most recent call last):
  File "/usr/local/lib/python3.9/site-packages/jupyter_cache/executors/utils.py", line 58, in single_nb_execution
    executenb(
  File "/usr/local/lib/python3.9/site-packages/nbclient/client.py", line 1112, in execute
    return NotebookClient(nb=nb, resources=resources, km=km, **kwargs).execute()
  File "/usr/local/lib/python3.9/site-packages/nbclient/util.py", line 74, in wrapped
    return just_run(coro(*args, **kwargs))
  File "/usr/local/lib/python3.9/site-packages/nbclient/util.py", line 53, in just_run
    return loop.run_until_complete(coro)
  File "/usr/local/Cellar/python@3.9/3.9.9/Frameworks/Python.framework/Versions/3.9/lib/python3.9/asyncio/base_events.py", line 642, in run_until_complete
    return future.result()
  File "/usr/local/lib/python3.9/site-packages/nbclient/client.py", line 553, in async_execute
    await self.async_execute_cell(
  File "/usr/local/lib/python3.9/site-packages/nbclient/client.py", line 857, in async_execute_cell
    self._check_raise_for_error(cell, exec_reply)
  File "/usr/local/lib/python3.9/site-packages/nbclient/client.py", line 760, in _check_raise_for_error
    raise CellExecutionError.from_cell_and_msg(cell, exec_reply_content)
nbclient.exceptions.CellExecutionError: An error occurred while executing the following cell:
------------------
auto_avg(adult['Capital Gain'], 1)
------------------

[0;31m---------------------------------------------------------------------------[0m
[0;31mKeyError[0m                                  Traceback (most recent call last)
[0;32m/usr/local/lib/python3.9/site-packages/pandas/core/indexes/base.py[0m in [0;36mget_loc[0;34m(self, key, method, tolerance)[0m
[1;32m   2894[0m             [0;32mtry[0m[0;34m:[0m[0;34m[0m[0;34m[0m[0m
[0;32m-> 2895[0;31m                 [0;32mreturn[0m [0mself[0m[0;34m.[0m[0m_engine[0m[0;34m.[0m[0mget_loc[0m[0;34m([0m[0mcasted_key[0m[0;34m)[0m[0;34m[0m[0;34m[0m[0m
[0m[1;32m   2896[0m             [0;32mexcept[0m [0mKeyError[0m [0;32mas[0m [0merr[0m[0;34m:[0m[0;34m[0m[0;34m[0m[0m

[0;32mpandas/_libs/index.pyx[0m in [0;36mpandas._libs.index.IndexEngine.get_loc[0;34m()[0m

[0;32mpandas/_libs/index.pyx[0m in [0;36mpandas._libs.index.IndexEngine.get_loc[0;34m()[0m

[0;32mpandas/_libs/hashtable_class_helper.pxi[0m in [0;36mpandas._libs.hashtable.PyObjectHashTable.get_item[0;34m()[0m

[0;32mpandas/_libs/hashtable_class_helper.pxi[0m in [0;36mpandas._libs.hashtable.PyObjectHashTable.get_item[0;34m()[0m

[0;31mKeyError[0m: 'Capital Gain'

The above exception was the direct cause of the following exception:

[0;31mKeyError[0m                                  Traceback (most recent call last)
[0;32m<ipython-input-10-5b72967cbeb8>[0m in [0;36m<module>[0;34m[0m
[0;32m----> 1[0;31m [0mauto_avg[0m[0;34m([0m[0madult[0m[0;34m[[0m[0;34m'Capital Gain'[0m[0;34m][0m[0;34m,[0m [0;36m1[0m[0;34m)[0m[0;34m[0m[0;34m[0m[0m
[0m
[0;32m/usr/local/lib/python3.9/site-packages/pandas/core/frame.py[0m in [0;36m__getitem__[0;34m(self, key)[0m
[1;32m   2904[0m             [0;32mif[0m [0mself[0m[0;34m.[0m[0mcolumns[0m[0;34m.[0m[0mnlevels[0m [0;34m>[0m [0;36m1[0m[0;34m:[0m[0;34m[0m[0;34m[0m[0m
[1;32m   2905[0m                 [0;32mreturn[0m [0mself[0m[0;34m.[0m[0m_getitem_multilevel[0m[0;34m([0m[0mkey[0m[0;34m)[0m[0;34m[0m[0;34m[0m[0m
[0;32m-> 2906[0;31m             [0mindexer[0m [0;34m=[0m [0mself[0m[0;34m.[0m[0mcolumns[0m[0;34m.[0m[0mget_loc[0m[0;34m([0m[0mkey[0m[0;34m)[0m[0;34m[0m[0;34m[0m[0m
[0m[1;32m   2907[0m             [0;32mif[0m [0mis_integer[0m[0;34m([0m[0mindexer[0m[0;34m)[0m[0;34m:[0m[0;34m[0m[0;34m[0m[0m
[1;32m   2908[0m                 [0mindexer[0m [0;34m=[0m [0;34m[[0m[0mindexer[0m[0;34m][0m[0;34m[0m[0;34m[0m[0m

[0;32m/usr/local/lib/python3.9/site-packages/pandas/core/indexes/base.py[0m in [0;36mget_loc[0;34m(self, key, method, tolerance)[0m
[1;32m   2895[0m                 [0;32mreturn[0m [0mself[0m[0;34m.[0m[0m_engine[0m[0;34m.[0m[0mget_loc[0m[0;34m([0m[0mcasted_key[0m[0;34m)[0m[0;34m[0m[0;34m[0m[0m
[1;32m   2896[0m             [0;32mexcept[0m [0mKeyError[0m [0;32mas[0m [0merr[0m[0;34m:[0m[0;34m[0m[0;34m[0m[0m
[0;32m-> 2897[0;31m                 [0;32mraise[0m [0mKeyError[0m[0;34m([0m[0mkey[0m[0;34m)[0m [0;32mfrom[0m [0merr[0m[0;34m[0m[0;34m[0m[0m
[0m[1;32m   2898[0m [0;34m[0m[0m
[1;32m   2899[0m         [0;32mif[0m [0mtolerance[0m [0;32mis[0m [0;32mnot[0m [0;32mNone[0m[0;34m:[0m[0;34m[0m[0;34m[0m[0m

[0;31mKeyError[0m: 'Capital Gain'
KeyError: 'Capital Gain'

